Traceback (most recent call last):
  File "/opt/hostedtoolcache/Python/3.10.13/x64/lib/python3.10/site-packages/jupyter_cache/executors/utils.py", line 58, in single_nb_execution
    executenb(
  File "/opt/hostedtoolcache/Python/3.10.13/x64/lib/python3.10/site-packages/nbclient/client.py", line 1305, in execute
    return NotebookClient(nb=nb, resources=resources, km=km, **kwargs).execute()
  File "/opt/hostedtoolcache/Python/3.10.13/x64/lib/python3.10/site-packages/jupyter_core/utils/__init__.py", line 165, in wrapped
    return loop.run_until_complete(inner)
  File "/opt/hostedtoolcache/Python/3.10.13/x64/lib/python3.10/asyncio/base_events.py", line 649, in run_until_complete
    return future.result()
  File "/opt/hostedtoolcache/Python/3.10.13/x64/lib/python3.10/site-packages/nbclient/client.py", line 705, in async_execute
    await self.async_execute_cell(
  File "/opt/hostedtoolcache/Python/3.10.13/x64/lib/python3.10/site-packages/nbclient/client.py", line 1058, in async_execute_cell
    await self._check_raise_for_error(cell, cell_index, exec_reply)
  File "/opt/hostedtoolcache/Python/3.10.13/x64/lib/python3.10/site-packages/nbclient/client.py", line 914, in _check_raise_for_error
    raise CellExecutionError.from_cell_and_msg(cell, exec_reply_content)
nbclient.exceptions.CellExecutionError: An error occurred while executing the following cell:
------------------
from sklearn.metrics import plot_confusion_matrix

_ = plot_confusion_matrix(decision_tree,
                          X_test,
                          y_test,
                          cmap=plt.cm.Greens,
                          normalize="true")
------------------


[0;31m---------------------------------------------------------------------------[0m
[0;31mImportError[0m                               Traceback (most recent call last)
Cell [0;32mIn[4], line 1[0m
[0;32m----> 1[0m [38;5;28;01mfrom[39;00m [38;5;21;01msklearn[39;00m[38;5;21;01m.[39;00m[38;5;21;01mmetrics[39;00m [38;5;28;01mimport[39;00m plot_confusion_matrix
[1;32m      3[0m _ [38;5;241m=[39m plot_confusion_matrix(decision_tree,
[1;32m      4[0m                           X_test,
[1;32m      5[0m                           y_test,
[1;32m      6[0m                           cmap[38;5;241m=[39mplt[38;5;241m.[39mcm[38;5;241m.[39mGreens,
[1;32m      7[0m                           normalize[38;5;241m=[39m[38;5;124m"[39m[38;5;124mtrue[39m[38;5;124m"[39m)

[0;31mImportError[0m: cannot import name 'plot_confusion_matrix' from 'sklearn.metrics' (/opt/hostedtoolcache/Python/3.10.13/x64/lib/python3.10/site-packages/sklearn/metrics/__init__.py)

