Traceback (most recent call last):
  File "/opt/hostedtoolcache/Python/3.8.17/x64/lib/python3.8/site-packages/jupyter_cache/executors/utils.py", line 58, in single_nb_execution
    executenb(
  File "/opt/hostedtoolcache/Python/3.8.17/x64/lib/python3.8/site-packages/nbclient/client.py", line 1305, in execute
    return NotebookClient(nb=nb, resources=resources, km=km, **kwargs).execute()
  File "/opt/hostedtoolcache/Python/3.8.17/x64/lib/python3.8/site-packages/jupyter_core/utils/__init__.py", line 166, in wrapped
    return loop.run_until_complete(inner)
  File "/opt/hostedtoolcache/Python/3.8.17/x64/lib/python3.8/asyncio/base_events.py", line 616, in run_until_complete
    return future.result()
  File "/opt/hostedtoolcache/Python/3.8.17/x64/lib/python3.8/site-packages/nbclient/client.py", line 705, in async_execute
    await self.async_execute_cell(
  File "/opt/hostedtoolcache/Python/3.8.17/x64/lib/python3.8/site-packages/nbclient/client.py", line 1058, in async_execute_cell
    await self._check_raise_for_error(cell, cell_index, exec_reply)
  File "/opt/hostedtoolcache/Python/3.8.17/x64/lib/python3.8/site-packages/nbclient/client.py", line 914, in _check_raise_for_error
    raise CellExecutionError.from_cell_and_msg(cell, exec_reply_content)
nbclient.exceptions.CellExecutionError: An error occurred while executing the following cell:
------------------
data = read_data()
------------------


[0;31m---------------------------------------------------------------------------[0m
[0;31mTypeError[0m                                 Traceback (most recent call last)
Cell [0;32mIn[2], line 1[0m
[0;32m----> 1[0m data [38;5;241m=[39m [43mread_data[49m[43m([49m[43m)[49m

File [0;32m~/work/ml_for_neuro/ml_for_neuro/ml_for_neuro/chapters/chapter_01/read_data.py:57[0m, in [0;36mread_data[0;34m()[0m
[1;32m     55[0m [38;5;66;03m# Read CSVs from remote location as a single dataframe.[39;00m
[1;32m     56[0m urls [38;5;241m=[39m [CSV_URL_PATTERN[38;5;241m.[39mformat(week_id[38;5;241m=[39mweek_id) [38;5;28;01mfor[39;00m week_id [38;5;129;01min[39;00m WEEK_IDS]
[0;32m---> 57[0m dataframes [38;5;241m=[39m [pd[38;5;241m.[39mread_csv(url, error_bad_lines[38;5;241m=[39m[38;5;28;01mFalse[39;00m) [38;5;28;01mfor[39;00m url [38;5;129;01min[39;00m urls]
[1;32m     58[0m data [38;5;241m=[39m pd[38;5;241m.[39mconcat(dataframes, ignore_index[38;5;241m=[39m[38;5;28;01mTrue[39;00m)
[1;32m     60[0m [38;5;66;03m# Convert COVID-19 test results to boolean values.[39;00m

File [0;32m~/work/ml_for_neuro/ml_for_neuro/ml_for_neuro/chapters/chapter_01/read_data.py:57[0m, in [0;36m<listcomp>[0;34m(.0)[0m
[1;32m     55[0m [38;5;66;03m# Read CSVs from remote location as a single dataframe.[39;00m
[1;32m     56[0m urls [38;5;241m=[39m [CSV_URL_PATTERN[38;5;241m.[39mformat(week_id[38;5;241m=[39mweek_id) [38;5;28;01mfor[39;00m week_id [38;5;129;01min[39;00m WEEK_IDS]
[0;32m---> 57[0m dataframes [38;5;241m=[39m [[43mpd[49m[38;5;241;43m.[39;49m[43mread_csv[49m[43m([49m[43murl[49m[43m,[49m[43m [49m[43merror_bad_lines[49m[38;5;241;43m=[39;49m[38;5;28;43;01mFalse[39;49;00m[43m)[49m [38;5;28;01mfor[39;00m url [38;5;129;01min[39;00m urls]
[1;32m     58[0m data [38;5;241m=[39m pd[38;5;241m.[39mconcat(dataframes, ignore_index[38;5;241m=[39m[38;5;28;01mTrue[39;00m)
[1;32m     60[0m [38;5;66;03m# Convert COVID-19 test results to boolean values.[39;00m

[0;31mTypeError[0m: read_csv() got an unexpected keyword argument 'error_bad_lines'

